Workbook

Sheet Sales
A1: Date | B1: Odrder ID | C1: Customer_Id | D1: Product_Id | E1: units_sold | F1: Total_Amount | G1: Store_ID
A2: 44431 | B2: ="sa-"&DAY(A2)&"-"&MONTH(A2) -> sa-23-8 | C2: CS_Sim_5 | D2: P10007 | E2: 5 | F2: =VLOOKUP(D2,Products!A$2:C$101,3,FALSE)*E2 -> 315 | G2: St_Pho_ A
A3: 44577 | B3: ="sa-"&DAY(A3)&"-"&MONTH(A3) -> sa-16-1 | C3: CS_Dav_37 | D3: P10073 | E3: 4 | F3: =VLOOKUP(D3,Products!A$2:C$101,3,FALSE)*E3 -> 136 | G3: St_Las_Ne
A4: 44396 | B4: ="sa-"&DAY(A4)&"-"&MONTH(A4) -> sa-19-7 | C4: CS_Dav_37 | D4: P10037 | E4: 4 | F4: =VLOOKUP(D4,Products!A$2:C$101,3,FALSE)*E4 -> 128 | G4: St_Las_Ne
A5: 44650 | B5: ="sa-"&DAY(A5)&"-"&MONTH(A5) -> sa-30-3 | C5: CS_Mat_12 | D5: P10082 | E5: 2 | F5: =VLOOKUP(D5,Products!A$2:C$101,3,FALSE)*E5 -> 60 | G5: St_Las_Ne
A6: 44590 | B6: ="sa-"&DAY(A6)&"-"&MONTH(A6) -> sa-29-1 | C6: CS_Bea_11 | D6: P10085 | E6: 5 | F6: =VLOOKUP(D6,Products!A$2:C$101,3,FALSE)*E6 -> 170 | G6: St_Atl_Ge
A7: 44187 | B7: ="sa-"&DAY(A7)&"-"&MONTH(A7) -> sa-22-12 | C7: CS_Kel_44 | D7: P10030 | E7: 5 | F7: =VLOOKUP(D7,Products!A$2:C$101,3,FALSE)*E7 -> 160 | G7: St_Hou_Te
A8: 44073 | B8: ="sa-"&DAY(A8)&"-"&MONTH(A8) -> sa-30-8 | C8: CS_Dav_15 | D8: P10037 | E8: 6 | F8: =VLOOKUP(D8,Products!A$2:C$101,3,FALSE)*E8 -> 192 | G8: St_Det_Mi
A9: 44220 | B9: ="sa-"&DAY(A9)&"-"&MONTH(A9) -> sa-24-1 | C9: CS_Don_33 | D9: P10031 | E9: 5 | F9: =VLOOKUP(D9,Products!A$2:C$101,3,FALSE)*E9 -> 170 | G9: St_Cha_No
A10: 44401 | B10: ="sa-"&DAY(A10)&"-"&MONTH(A10) -> sa-24-7 | C10: CS_Cal_22 | D10: P10066 | E10: 3 | F10: =VLOOKUP(D10,Products!A$2:C$101,3,FALSE)*E10 -> 96 | G10: St_Pho_ A
A11: 44716 | B11: ="sa-"&DAY(A11)&"-"&MONTH(A11) -> sa-4-6 | C11: CS_Com_17 | D11: P10032 | E11: 6 | F11: =VLOOKUP(D11,Products!A$2:C$101,3,FALSE)*E11 -> 198 | G11: St_Ind_In
A12: 43914 | B12: ="sa-"&DAY(A12)&"-"&MONTH(A12) -> sa-24-3 | C12: CS_Loi_30 | D12: P10098 | E12: 4 | F12: =VLOOKUP(D12,Products!A$2:C$101,3,FALSE)*E12 -> 60 | G12: St_Det_Mi
A13: 44418 | B13: ="sa-"&DAY(A13)&"-"&MONTH(A13) -> sa-10-8 | C13: CS_Jon_20 | D13: P10025 | E13: 2 | F13: =VLOOKUP(D13,Products!A$2:C$101,3,FALSE)*E13 -> 66 | G13: St_Okl_Ok
... A2000: 44005 | B2000: ="sa-"&DAY(A2000)&"-"&MONTH(A2000) -> sa-23-6 | C2000: CS_Nol_49 | D2000: P10071 | E2000: 3 | F2000: =VLOOKUP(D2000,Products!A$2:C$101,3,FALSE)*E2000 -> 93 | G2000: St_Las_Ne

Sheet Customers
A1: Customer_Id | B1: Fisrt _Name | C1: Last_NAME | D1: Gender | E1: city
A2: {="CS_"&LEFT(B2,3)&"_"&ROW(2:2)} -> CS_Gut_2 | B2: Gutierrez | C2: Molly | D2: F | E2: Baltimore
A3: {="CS_"&LEFT(B3,3)&"_"&ROW(3:3)} -> CS_Har_3 | B3: Hardwick | C3: Stephen | D3: M | E3: Las Vegas
A4: {="CS_"&LEFT(B4,3)&"_"&ROW(4:4)} -> CS_Del_4 | B4: Delgado | C4: Chester | D4: M | E4: Oklahoma City
A5: {="CS_"&LEFT(B5,3)&"_"&ROW(5:5)} -> CS_Sim_5 | B5: Simon | C5: Irene | D5: F | E5: Baltimore
A6: {="CS_"&LEFT(B6,3)&"_"&ROW(6:6)} -> CS_Del_6 | B6: Delvalle | C6: Edward | D6: M | E6: Detroit
A7: {="CS_"&LEFT(B7,3)&"_"&ROW(7:7)} -> CS_Jon_7 | B7: Jones | C7: Ernie | D7: M | E7: Charlotte
A8: {="CS_"&LEFT(B8,3)&"_"&ROW(8:8)} -> CS_Buf_8 | B8: Buford | C8: Ralph | D8: M | E8: Oklahoma City
A9: {="CS_"&LEFT(B9,3)&"_"&ROW(9:9)} -> CS_Lee_9 | B9: Lee | C9: Gregory | D9: M | E9: Phoenix
A10: {="CS_"&LEFT(B10,3)&"_"&ROW(10:10)} -> CS_Smi_10 | B10: Smith | C10: Jerry | D10: M | E10: Atlanta
A11: {="CS_"&LEFT(B11,3)&"_"&ROW(11:11)} -> CS_Bea_11 | B11: Beard | C11: Robert | D11: M | E11: Indianapolis
A12: {="CS_"&LEFT(B12,3)&"_"&ROW(12:12)} -> CS_Mat_12 | B12: Mathis | C12: John | D12: M | E12: Phoenix
A13: {="CS_"&LEFT(B13,3)&"_"&ROW(13:13)} -> CS_Bar_13 | B13: Barajas | C13: John | D13: M | E13: Columbus
A14: {="CS_"&LEFT(B14,3)&"_"&ROW(14:14)} -> CS_Leo_14 | B14: Leonard | C14: James | D14: M | E14: Las Vegas
A15: {="CS_"&LEFT(B15,3)&"_"&ROW(15:15)} -> CS_Dav_15 | B15: Davis | C15: Janet | D15: F | E15: Houston
A16: {="CS_"&LEFT(B16,3)&"_"&ROW(16:16)} -> CS_Bel_16 | B16: Bell | C16: Thomas | D16: M | E16: Charlotte
A17: {="CS_"&LEFT(B17,3)&"_"&ROW(17:17)} -> CS_Com_17 | B17: Combs | C17: Danny | D17: M | E17: Seattle
A18: {="CS_"&LEFT(B18,3)&"_"&ROW(18:18)} -> CS_Viv_18 | B18: Vivanco | C18: Anne | D18: F | E18: Detroit
A19: {="CS_"&LEFT(B19,3)&"_"&ROW(19:19)} -> CS_Cra_19 | B19: Craig | C19: Bobbie | D19: F | E19: Columbus
A20: {="CS_"&LEFT(B20,3)&"_"&ROW(20:20)} -> CS_Jon_20 | B20: Jones | C20: Ilona | D20: F | E20: Columbus
A21: {="CS_"&LEFT(B21,3)&"_"&ROW(21:21)} -> CS_Wat_21 | B21: Watkins | C21: Jan | D21: F | E21: Seattle
A22: {="CS_"&LEFT(B22,3)&"_"&ROW(22:22)} -> CS_Cal_22 | B22: Callaway | C22: Jesus | D22: M | E22: Columbus
A23: {="CS_"&LEFT(B23,3)&"_"&ROW(23:23)} -> CS_Ham_23 | B23: Hammett | C23: Josephine | D23: F | E23: Los Angeles
A24: {="CS_"&LEFT(B24,3)&"_"&ROW(24:24)} -> CS_Jar_24 | B24: Jarman | C24: Sandra | D24: F | E24: Detroit
A25: {="CS_"&LEFT(B25,3)&"_"&ROW(25:25)} -> CS_But_25 | B25: Butler | C25: Jennifer | D25: F | E25: Seattle
A26: {="CS_"&LEFT(B26,3)&"_"&ROW(26:26)} -> CS_Sim_26 | B26: Simons | C26: Larry | D26: M | E26: Baltimore
A27: {="CS_"&LEFT(B27,3)&"_"&ROW(27:27)} -> CS_Mas_27 | B27: Mason | C27: Penny | D27: F | E27: Baltimore
A28: {="CS_"&LEFT(B28,3)&"_"&ROW(28:28)} -> CS_Bur_28 | B28: Burton | C28: Theodore | D28: M | E28: Miami
A29: {="CS_"&LEFT(B29,3)&"_"&ROW(29:29)} -> CS_Hun_29 | B29: Hunt | C29: Joseph | D29: M | E29: Charlotte
A30: {="CS_"&LEFT(B30,3)&"_"&ROW(30:30)} -> CS_Loi_30 | B30: Loiselle | C30: Thomas | D30: M | E30: Oklahoma City
A31: {="CS_"&LEFT(B31,3)&"_"&ROW(31:31)} -> CS_Ngu_31 | B31: Nguyen | C31: William | D31: M | E31: Columbus
A32: {="CS_"&LEFT(B32,3)&"_"&ROW(32:32)} -> CS_Sch_32 | B32: Schrupp | C32: James | D32: M | E32: Albuquerque
A33: {="CS_"&LEFT(B33,3)&"_"&ROW(33:33)} -> CS_Don_33 | B33: Donaldson | C33: Adriana | D33: F | E33: Oklahoma City
A34: {="CS_"&LEFT(B34,3)&"_"&ROW(34:34)} -> CS_Tho_34 | B34: Thompson | C34: Felipe | D34: M | E34: Los Angeles
A35: {="CS_"&LEFT(B35,3)&"_"&ROW(35:35)} -> CS_Liv_35 | B35: Livingston | C35: Lester | D35: M | E35: Baltimore
A36: {="CS_"&LEFT(B36,3)&"_"&ROW(36:36)} -> CS_Ash_36 | B36: Ashley | C36: Emma | D36: F | E36: Houston
A37: {="CS_"&LEFT(B37,3)&"_"&ROW(37:37)} -> CS_Dav_37 | B37: Davis | C37: Jeffery | D37: M | E37: Houston
A38: {="CS_"&LEFT(B38,3)&"_"&ROW(38:38)} -> CS_Far_38 | B38: Farris | C38: Augustina | D38: F | E38: Detroit
A39: {="CS_"&LEFT(B39,3)&"_"&ROW(39:39)} -> CS_Col_39 | B39: Colman | C39: Katherine | D39: F | E39: Charlotte
A40: {="CS_"&LEFT(B40,3)&"_"&ROW(40:40)} -> CS_Mar_40 | B40: Martin | C40: Daniel | D40: M | E40: Las Vegas
...

Sheet Products
A1: Product_Id | B1: Product Name | C1: Product Price | D1: Product Category
A2: P10001 | B2: Air purifier | C2: 66 | D2: Electronics
A3: P10002 | B3: Air conditioner | C3: 74 | D3: Electronics
A4: P10003 | B4: Alarm clock | C4: 71 | D4: Electronics
A5: P10004 | B5: Backup charger | C5: 80 | D5: Electronics
A6: P10005 | B6: Bread maker | C6: 69 | D6: Electronics
A7: P10006 | B7: Banknote counter | C7: 74 | D7: Electronics
A8: P10007 | B8: Blender | C8: 63 | D8: Electronics
A9: P10008 | B9: Bluetooth speaker | C9: 80 | D9: Electronics
A10: P10009 | B10: Clothes dryer | C10: 72 | D10: Electronics
A11: P10010 | B11: Coffee maker | C11: 78 | D11: Electronics
A12: P10011 | B12: Computer | C12: 74 | D12: Electronics
A13: P10012 | B13: Copier | C13: 71 | D13: Electronics
... A101: P10100 | B101: Rice Dry Dog Food | C101: 10 | D101: Pet Supplies

Sheet Stores
A1: Store_ID | B1: City | C1: State | D1: Location
A2: ="St_"&LEFT(B2,3)&"_"&LEFT(C2,2) -> St_Atl_Ge | B2: Atlanta | C2: Georgia | D2: East Coast
A3: ="St_"&LEFT(B3,3)&"_"&LEFT(C3,2) -> St_Mia_Fl | B3: Miami | C3: Florida | D3: East Coast
A4: ="St_"&LEFT(B4,3)&"_"&LEFT(C4,2) -> St_Bal_Ma | B4: Baltimore | C4: Maryland | D4: East Coast
A5: ="St_"&LEFT(B5,3)&"_"&LEFT(C5,2) -> St_Cha_No | B5: Charlotte | C5: North Carolina | D5: East Coast
A6: ="St_"&LEFT(B6,3)&"_"&LEFT(C6,2) -> St_Det_Mi | B6: Detroit | C6: Michigan | D6: Midwest
A7: ="St_"&LEFT(B7,3)&"_"&LEFT(C7,2) -> St_Col_Oh | B7: Columbus | C7: Ohio | D7: Midwest
A8: ="St_"&LEFT(B8,3)&"_"&LEFT(C8,2) -> St_Ind_In | B8: Indianapolis | C8: Indiana | D8: Midwest
A9: ="St_"&LEFT(B9,3)&"_"&LEFT(C9,2) -> St_Pho_ A | B9: Phoenix | C9: Arizona | D9: Southwest
A10: ="St_"&LEFT(B10,3)&"_"&LEFT(C10,2) -> St_Alb_ N | B10: Albuquerque | C10: New Mexico | D10: Southwest
A11: ="St_"&LEFT(B11,3)&"_"&LEFT(C11,2) -> St_Okl_Ok | B11: Oklahoma City | C11: Oklahoma | D11: Southwest
A12: ="St_"&LEFT(B12,3)&"_"&LEFT(C12,2) -> St_Hou_Te | B12: Houston | C12: Texas | D12: Southwest
A13: ="St_"&LEFT(B13,3)&"_"&LEFT(C13,2) -> St_Los_Ca | B13: Los Angeles | C13: California | D13: Far West
... A15: ="St_"&LEFT(B15,3)&"_"&LEFT(C15,2) -> St_Sea_Wa | B15: Seattle | C15: Washington | D15: Far West
